Workbook

Sheet BG - ER
A1: DROGUERIA INTI S.A.
A2: BALANCE GENERAL | I2: para identificar las cuentas que son mas importantes/ relevantes
I3: ANALISIS VERTICAL | O3: ANALISIS HORIZONTAL
B4: NOTAS | C4: 2020 | D4: 2021 | E4: 2022 | F4: 2023 | G4: 2024 | I4: 2020 | J4: 2021 | K4: 2022 | L4: 2023 | M4: 2024 | O4: 2021/2020 | P4: 2022/2021 | Q4: 2023/2022 | R4: 2024/2023
A5: ACTIVO CORRIENTE
A6: Disponiblidades | B6: 3 | C6: 189314286 | D6: 296012825 | E6: 320186324 | F6: 144061536 | G6: 116138957 | I6: =C6/C$23 -> 0.21309635 | J6: =D6/D$23 -> 0.30346763 | K6: =E6/E$23 -> 0.30759588 | L6: =F6/F$23 -> 0.12635566 | M6: =G6/G$23 -> 0.096619309 | O6: =IFERROR((D6-C6)/C6,0) -> 0.56360532 | P6: =IFERROR((E6-D6)/D6,0) -> 0.081663688 | Q6: =IFERROR((F6-E6)/E6,0) -> -0.55006968 | R6: =IFERROR((G6-F6)/F6,0) -> -0.19382397
A7: Inversiones temporarias | B7: 8 | C7: 0 | D7: 0 | E7: 7140830 | F7: 85523883 | G7: 153641074 | I7: =C7/C$23 -> 0 | J7: =D7/D$23 -> 0 | K7: =E7/E$23 -> 0.0068600364 | L7: =F7/F$23 -> 0.075012576 | M7: =G7/G$23 -> 0.12781839 | O7: =IFERROR((D7-C7)/C7,0) -> 0 | P7: =IFERROR((E7-D7)/D7,0) -> 0 | Q7: =IFERROR((F7-E7)/E7,0) -> 10.976743 | R7: =IFERROR((G7-F7)/F7,0) -> 0.79646981
A8: Cuentas por cobrar comerciales | B8: 4 | C8: 155012353 | D8: 73492069 | E8: 80506889 | F8: 98202419 | G8: 130005950 | I8: =C8/C$23 -> 0.17448533 | J8: =D8/D$23 -> 0.075342899 | K8: =E8/E$23 -> 0.077341176 | L8: =F8/F$23 -> 0.086132858 | M8: =G8/G$23 -> 0.10815566 | O8: =IFERROR((D8-C8)/C8,0) -> -0.5258954 | P8: =IFERROR((E8-D8)/D8,0) -> 0.095450027 | Q8: =IFERROR((F8-E8)/E8,0) -> 0.21980144 | R8: =IFERROR((G8-F8)/F8,0) -> 0.3238569
A9: Otras cuentas por cobrar | B9: 5 | C9: 3999913 | D9: 8380208 | E9: 5402004 | F9: 7126636 | G9: 846468 | I9: =C9/C$23 -> 0.0045023905 | J9: =D9/D$23 -> 0.0085912558 | K9: =E9/E$23 -> 0.005189585 | L9: =F9/F$23 -> 0.0062507373 | M9: =G9/G$23 -> 0.00070420086 | O9: =IFERROR((D9-C9)/C9,0) -> 1.0950976 | P9: =IFERROR((E9-D9)/D9,0) -> -0.35538545 | Q9: =IFERROR((F9-E9)/E9,0) -> 0.31925782 | R9: =IFERROR((G9-F9)/F9,0) -> -0.88122475
A10: Pagos anticipados | B10: 6 | C10: 23753262 | D10: 42837389 | E10: 46146335 | F10: 32812112 | G10: 21325607 | I10: =C10/C$23 -> 0.026737197 | J10: =D10/D$23 -> 0.043916209 | K10: =E10/E$23 -> 0.044331757 | L10: =F10/F$23 -> 0.028779342 | M10: =G10/G$23 -> 0.01774138 | O10: =IFERROR((D10-C10)/C10,0) -> 0.80343184 | P10: =IFERROR((E10-D10)/D10,0) -> 0.077244344 | Q10: =IFERROR((F10-E10)/E10,0) -> -0.28895519 | R10: =IFERROR((G10-F10)/F10,0) -> -0.35006905
A11: Inventarios | B11: 7 | C11: 245714352 | D11: 258735251 | E11: 217018095 | F11: 247210164 | G11: 266990453 | I11: =C11/C$23 -> 0.27658151 | J11: =D11/D$23 -> 0.26525126 | K11: =E11/E$23 -> 0.20848445 | L11: =F11/F$23 -> 0.21682682 | M11: =G11/G$23 -> 0.22211697 | O11: =IFERROR((D11-C11)/C11,0) -> 0.052992017 | P11: =IFERROR((E11-D11)/D11,0) -> -0.16123491 | Q11: =IFERROR((F11-E11)/E11,0) -> 0.13912236 | R11: =IFERROR((G11-F11)/F11,0) -> 0.08001406
A12: Total activo corriente | C12: =SUM(C6:C11) -> 617794166 | D12: =SUM(D6:D11) -> 679457742 | E12: =SUM(E6:E11) -> 676400477 | F12: =SUM(F6:F11) -> 614936750 | G12: =SUM(G6:G11) -> 688948509 | I12: =C12/C$23 -> 0.69540277 | J12: =D12/D$23 -> 0.69656926 | K12: =E12/E$23 -> 0.64980288 | L12: =F12/F$23 -> 0.53935799 | M12: =G12/G$23 -> 0.5731559 | O12: =IFERROR((D12-C12)/C12,0) -> 0.099812493 | P12: =IFERROR((E12-D12)/D12,0) -> -0.0044995661 | Q12: =IFERROR((F12-E12)/E12,0) -> -0.09086884 | R12: =IFERROR((G12-F12)/F12,0) -> 0.1203567
A13: ACTIVO NO CORRIENTE
A14: Cuentas por cobrar comerciales | B14: 4
A15: Inventarios | B15: 7 | C15: 17211103 | D15: 19736761 | E15: 41077832 | F15: 44204071 | G15: 34724547 | I15: =C15/C$23 -> 0.019373198 | J15: =D15/D$23 -> 0.020233813 | K15: =E15/E$23 -> 0.039462559 | L15: =F15/F$23 -> 0.038771173 | M15: =G15/G$23 -> 0.028888341 | O15: =IFERROR((D15-C15)/C15,0) -> 0.14674585 | P15: =IFERROR((E15-D15)/D15,0) -> 1.0812854 | Q15: =IFERROR((F15-E15)/E15,0) -> 0.076105258 | R15: =IFERROR((G15-F15)/F15,0) -> -0.21444912
A16: Inversiones permanente | B16: 8 | C16: 17645872 | D16: 18454691 | E16: 23548559 | F16: 139278979 | G16: 79610392 | I16: =C16/C$23 -> 0.019862584 | J16: =D16/D$23 -> 0.018919455 | K16: =E16/E$23 -> 0.022622577 | L16: =F16/F$23 -> 0.12216091 | M16: =G16/G$23 -> 0.066230155 | O16: =IFERROR((D16-C16)/C16,0) -> 0.045836159 | P16: =IFERROR((E16-D16)/D16,0) -> 0.27602023 | Q16: =IFERROR((F16-E16)/E16,0) -> 4.9145436 | R16: =IFERROR((G16-F16)/F16,0) -> -0.42841057
A17: Activo fijo neto | B17: 9 | C17: 232616033 | D17: 253072936 | E17: 296661987 | F17: 340471457 | G17: 397659375 | I17: =C17/C$23 -> 0.26183775 | J17: =D17/D$23 -> 0.25944634 | K17: =E17/E$23 -> 0.28499657 | L17: =F17/F$23 -> 0.29862584 | M17: =G17/G$23 -> 0.33082417 | O17: =IFERROR((D17-C17)/C17,0) -> 0.08794279 | P17: =IFERROR((E17-D17)/D17,0) -> 0.17223909 | Q17: =IFERROR((F17-E17)/E17,0) -> 0.1476747 | R17: =IFERROR((G17-F17)/F17,0) -> 0.16796685
A18: Activo Fijo Bruto | C18: =+C17+C19 -> 473433455 | D18: =+D17+D19 -> 513341807 | E18: =+E17+E19 -> 575494715 | F18: =+F17+F19 -> 638991287 | G18: =+G17+G19 -> 696179205
A19: Depreciacion acumulada | C19: =+NOTAS!C90 -> 240817422 | D19: =+NOTAS!C102 -> 260268871 | E19: =+NOTAS!C114 -> 278832728 | F19: =+NOTAS!C126 -> 298519830 | G19: =+NOTAS!C138 -> 298519830
A20: Otros activos | B20: 10 | C20: 3130446 | D20: 4712452 | E20: 3242932 | F20: 1236001 | G20: 1083544 | I20: =C20/C$23 -> 0.0035236992 | J20: =D20/D$23 -> 0.0048311307 | K20: =E20/E$23 -> 0.0031154126 | L20: =F20/F$23 -> 0.0010840904 | M20: =G20/G$23 -> 0.00090143114 | O20: =IFERROR((D20-C20)/C20,0) -> 0.50536122 | P20: =IFERROR((E20-D20)/D20,0) -> -0.31183766 | Q20: =IFERROR((F20-E20)/E20,0) -> -0.61886312 | R20: =IFERROR((G20-F20)/F20,0) -> -0.12334699
A21: Total activo no corriente | C21: =SUM(C14:C17)+C20 -> 270603454 | D21: =SUM(D14:D17)+D20 -> 295976840 | E21: =SUM(E14:E17)+E20 -> 364531310 | F21: =SUM(F14:F17)+F20 -> 525190508 | G21: =SUM(G14:G17)+G20 -> 513077858 | I21: =C21/C$23 -> 0.30459723 | J21: =D21/D$23 -> 0.30343074 | K21: =E21/E$23 -> 0.35019712 | L21: =F21/F$23 -> 0.46064201 | M21: =G21/G$23 -> 0.4268441 | O21: =IFERROR((D21-C21)/C21,0) -> 0.093765935 | P21: =IFERROR((E21-D21)/D21,0) -> 0.23162106 | Q21: =IFERROR((F21-E21)/E21,0) -> 0.44072812 | R21: =IFERROR((G21-F21)/F21,0) -> -0.023063345
A23: TOTAL ACTIVO | C23: =C12+C21 -> 888397620 | D23: =D12+D21 -> 975434582 | E23: =E12+E21 -> 1040931787 | F23: =F12+F21 -> 1140127258 | G23: =G12+G21 -> 1202026367 | I23: =C23/C$23 -> 1 | J23: =D23/D$23 -> 1 | K23: =E23/E$23 -> 1 | L23: =F23/F$23 -> 1 | M23: =G23/G$23 -> 1 | O23: =IFERROR((D23-C23)/C23,0) -> 0.097970728 | P23: =IFERROR((E23-D23)/D23,0) -> 0.067146692 | Q23: =IFERROR((F23-E23)/E23,0) -> 0.095294881 | R23: =IFERROR((G23-F23)/F23,0) -> 0.054291403
A25: Cuentas de orden deudoras
A26: Mercaderias en consignación | C26: 66602824 | D26: 0 | E26: 139773 | F26: 0 | G26: 0
A28: PASIVO CORRIENTE
A29: Deudores comerciales | B29: 11 | C29: 100024306 | D29: 59873420 | E29: 52791621 | F29: 74793153 | G29: 92496321 | I29: =C29/C$46 -> 0.11258957 | J29: =D29/D$46 -> 0.061381277 | K29: =E29/E$46 -> 0.050715735 | L29: =F29/F$46 -> 0.065600706 | M29: =G29/G$46 -> 0.076949174 | O29: =IFERROR((D29-C29)/C29,0) -> -0.40141129 | P29: =IFERROR((E29-D29)/D29,0) -> -0.11827951 | Q29: =IFERROR((F29-E29)/E29,0) -> 0.41676182 | R29: =IFERROR((G29-F29)/F29,0) -> 0.23669504
A30: Deudas diversas | C30: 315768 | D30: 338681 | E30: 443118 | F30: 989415 | G30: 3974082 | I30: =C30/C$46 -> 0.00035543544 | J30: =D30/D$46 -> 0.00034721037 | K30: =E30/E$46 -> 0.0004256936 | L30: =F30/F$46 -> 0.00086781102 | M30: =G30/G$46 -> 0.0033061026 | O30: =IFERROR((D30-C30)/C30,0) -> 0.072562768 | P30: =IFERROR((E30-D30)/D30,0) -> 0.30836392 | Q30: =IFERROR((F30-E30)/E30,0) -> 1.2328477 | R30: =IFERROR((G30-F30)/F30,0) -> 3.0165977
A31: Obligaciones financieras | B31: 12 | C31: 2440086 | D31: 11305679 | E31: 7449816 | F31: 16492256 | G31: 37195218 | I31: =C31/C$46 -> 0.0027466147 | J31: =D31/D$46 -> 0.011590402 | K31: =E31/E$46 -> 0.0071568724 | L31: =F31/F$46 -> 0.014465276 | M31: =G31/G$46 -> 0.030943299 | O31: =IFERROR((D31-C31)/C31,0) -> 3.6333117 | P31: =IFERROR((E31-D31)/D31,0) -> -0.34105541 | Q31: =IFERROR((F31-E31)/E31,0) -> 1.2137803 | R31: =IFERROR((G31-F31)/F31,0) -> 1.2553141
A32: Bonos y pagares bursatiles | B32: 13 | C32: 10119105 | D32: 10086138 | E32: 15139054 | F32: 14147110 | G32: 15379654 | I32: =C32/C$46 -> 0.011390288 | J32: =D32/D$46 -> 0.010340148 | K32: =E32/E$46 -> 0.014543752 | L32: =F32/F$46 -> 0.01240836 | M32: =G32/G$46 -> 0.012794581 | O32: =IFERROR((D32-C32)/C32,0) -> -0.0032578968 | P32: =IFERROR((E32-D32)/D32,0) -> 0.50097629 | Q32: =IFERROR((F32-E32)/E32,0) -> -0.065522192 | R32: =IFERROR((G32-F32)/F32,0) -> 0.087123377
A33: Impuestos y cargas sociales por pagar | B33: 14 | C33: 44189843 | D33: 52414079 | E33: 63417833 | F33: 40743610 | G33: 37064161 | I33: =C33/C$46 -> 0.049741064 | J33: =D33/D$46 -> 0.053734079 | K33: =E33/E$46 -> 0.060924101 | L33: =F33/F$46 -> 0.03573602 | M33: =G33/G$46 -> 0.03083427 | O33: =IFERROR((D33-C33)/C33,0) -> 0.18611146 | P33: =IFERROR((E33-D33)/D33,0) -> 0.2099389 | Q33: =IFERROR((F33-E33)/E33,0) -> -0.35753702 | R33: =IFERROR((G33-F33)/F33,0) -> -0.090307388
A34: Dividendos por pagar | C34: 0 | D34: 0 | E34: 0 | F34: 10910000 | G34: 0 | I34: =C34/C$46 -> 0 | J34: =D34/D$46 -> 0 | K34: =E34/E$46 -> 0 | L34: =F34/F$46 -> 0.0095691072 | M34: =G34/G$46 -> 0 | O34: =IFERROR((D34-C34)/C34,0) -> 0 | P34: =IFERROR((E34-D34)/D34,0) -> 0 | Q34: =IFERROR((F34-E34)/E34,0) -> 0 | R34: =IFERROR((G34-F34)/F34,0) -> -1
A35: Total pasivo corriente | C35: =SUM(C29:C34) -> 157089108 | D35: =SUM(D29:D34) -> 134017997 | E35: =SUM(E29:E34) -> 139241442 | F35: =SUM(F29:F34) -> 158075544 | G35: =SUM(G29:G34) -> 186109436 | I35: =C35/C$46 -> 0.17682297 | J35: =D35/D$46 -> 0.13739312 | K35: =E35/E$46 -> 0.13376615 | L35: =F35/F$46 -> 0.13864728 | M35: =G35/G$46 -> 0.15482743 | O35: =IFERROR((D35-C35)/C35,0) -> -0.1468664 | P35: =IFERROR((E35-D35)/D35,0) -> 0.038975698 | Q35: =IFERROR((F35-E35)/E35,0) -> 0.13526219 | R35: =IFERROR((G35-F35)/F35,0) -> 0.1773449
A36: PASIVO NO CORRIENTE
A37: Deudas comerciales | C37: 0 | D37: 0 | E37: 1168076 | F37: 0 | O37: =IFERROR((D37-C37)/C37,0) -> 0 | P37: =IFERROR((E37-D37)/D37,0) -> 0 | Q37: =IFERROR((F37-E37)/E37,0) -> -1 | R37: =IFERROR((G37-F37)/F37,0) -> 0
A38: Obligaciones financieras | B38: 12 | C38: 18786827 | D38: 35973732 | E38: 44129798 | F38: 113569031 | G38: 124948263 | I38: =C38/C$46 -> 0.021146868 | J38: =D38/D$46 -> 0.036879697 | K38: =E38/E$46 -> 0.042394515 | L38: =F38/F$46 -> 0.099610837 | M38: =G38/G$46 -> 0.10394647 | O38: =IFERROR((D38-C38)/C38,0) -> 0.91483809 | P38: =IFERROR((E38-D38)/D38,0) -> 0.22672282 | Q38: =IFERROR((F38-E38)/E38,0) -> 1.5735226 | R38: =IFERROR((G38-F38)/F38,0) -> 0.10019661
A39: Bonos y pagares bursatiles | B39: 13 | C39: 115857320 | D39: 107030184 | E39: 93101832 | F39: 80003808 | G39: 65076000 | I39: =C39/C$46 -> 0.13041156 | J39: =D39/D$46 -> 0.10972564 | K39: =E39/E$46 -> 0.089440858 | L39: =F39/F$46 -> 0.070170946 | M39: =G39/G$46 -> 0.054137769 | O39: =IFERROR((D39-C39)/C39,0) -> -0.076189713 | P39: =IFERROR((E39-D39)/D39,0) -> -0.1301348 | Q39: =IFERROR((F39-E39)/E39,0) -> -0.14068492 | R39: =IFERROR((G39-F39)/F39,0) -> -0.18658872
A40: Previcion para indemnizaciones | C40: 37163261 | D40: 41908071 | E40: 38995496 | F40: 41068320 | G40: 42111365 | I40: =C40/C$46 -> 0.041831788 | J40: =D40/D$46 -> 0.042963487 | K40: =E40/E$46 -> 0.037462105 | L40: =F40/F$46 -> 0.036020821 | M40: =G40/G$46 -> 0.03503312 | O40: =IFERROR((D40-C40)/C40,0) -> 0.12767475 | P40: =IFERROR((E40-D40)/D40,0) -> -0.069499143 | Q40: =IFERROR((F40-E40)/E40,0) -> 0.053155472 | R40: =IFERROR((G40-F40)/F40,0) -> 0.025397801
A41: Total pasivo no corriente | C41: =SUM(C38:C40) -> 171807408 | D41: =SUM(D38:D40) -> 184911987 | E41: =SUM(E37:E40) -> 177395202 | F41: =SUM(F38:F40) -> 234641159 | G41: =SUM(G38:G40) -> 232135628 | I41: =C41/C$46 -> 0.19339022 | J41: =D41/D$46 -> 0.18956882 | K41: =E41/E$46 -> 0.17041962 | L41: =F41/F$46 -> 0.2058026 | M41: =G41/G$46 -> 0.19311735 | O41: =IFERROR((D41-C41)/C41,0) -> 0.076274819 | P41: =IFERROR((E41-D41)/D41,0) -> -0.04065061 | Q41: =IFERROR((F41-E41)/E41,0) -> 0.32270296 | R41: =IFERROR((G41-F41)/F41,0) -> -0.010678139
A43: TOTAL PASIVO | C43: =SUM(C35+C41) -> 328896516 | D43: =SUM(D35+D41) -> 318929984 | E43: =SUM(E35+E41) -> 316636644 | F43: =SUM(F35+F41) -> 392716703 | G43: =SUM(G35+G41) -> 418245064 | I43: =C43/C$46 -> 0.37021319 | J43: =D43/D$46 -> 0.32696194 | K43: =E43/E$46 -> 0.30418578 | L43: =F43/F$46 -> 0.34444989 | M43: =G43/G$46 -> 0.34794478 | O43: =IFERROR((D43-C43)/C43,0) -> -0.030302942 | P43: =IFERROR((E43-D43)/D43,0) -> -0.0071907319 | Q43: =IFERROR((F43-E43)/E43,0) -> 0.2402756 | R43: =IFERROR((G43-F43)/F43,0) -> 0.065004521
K44: =E44/E$46 -> 0 | O44: =IFERROR((D44-C44)/C44,0) -> 0 | P44: =IFERROR((E44-D44)/D44,0) -> 0 | Q44: =IFERROR((F44-E44)/E44,0) -> 0 | R44: =IFERROR((G44-F44)/F44,0) -> 0
...

Sheet Hoja1
A3: DETALLE | B3: 2021 | C3: 2022 | D3: 2023 | E3: 2024
A4: UTILIDAD NETA AJUSTADA | B4: =+'BG - ER'!E88+'BG - ER'!E78 -> 103110696 | C4: =+'BG - ER'!F88+'BG - ER'!F78 -> 63411341 | D4: =+'BG - ER'!G88+'BG - ER'!G78 -> 77918780 | E4: =+'BG - ER'!H88+'BG - ER'!H78 -> 0
A5: MAS: DEPRECIACION | B5: ='BG - ER'!D19-'BG - ER'!C19 -> 19451449 | C5: ='BG - ER'!E19-'BG - ER'!D19 -> 18563857 | D5: ='BG - ER'!F19-'BG - ER'!E19 -> 19687102 | E5: ='BG - ER'!G19-'BG - ER'!F19 -> 0
A6: Cuentas por cobrar comerciales | B6: =-('BG - ER'!D8-'BG - ER'!C8) -> 81520284 | C6: =-('BG - ER'!E8-'BG - ER'!D8) -> -7014820 | D6: =-('BG - ER'!F8-'BG - ER'!E8) -> -17695530 | E6: =-('BG - ER'!G8-'BG - ER'!F8) -> -31803531
A7: Otras cuentas por cobrar | B7: =-('BG - ER'!D9-'BG - ER'!C9) -> -4380295 | C7: =-('BG - ER'!E9-'BG - ER'!D9) -> 2978204 | D7: =-('BG - ER'!F9-'BG - ER'!E9) -> -1724632 | E7: =-('BG - ER'!G9-'BG - ER'!F9) -> 6280168
A8: Pagos anticipados | B8: =-('BG - ER'!D10-'BG - ER'!C10) -> -19084127 | C8: =-('BG - ER'!E10-'BG - ER'!D10) -> -3308946 | D8: =-('BG - ER'!F10-'BG - ER'!E10) -> 13334223 | E8: =-('BG - ER'!G10-'BG - ER'!F10) -> 11486505
A9: Inventarios | B9: =-('BG - ER'!D11-'BG - ER'!C11) -> -13020899 | C9: =-('BG - ER'!E11-'BG - ER'!D11) -> 41717156 | D9: =-('BG - ER'!F11-'BG - ER'!E11) -> -30192069 | E9: =-('BG - ER'!G11-'BG - ER'!F11) -> -19780289
A10: Cuentas por cobrar comerciales | B10: =-('BG - ER'!D14-'BG - ER'!C14) -> 0 | C10: =-('BG - ER'!E14-'BG - ER'!D14) -> 0 | D10: =-('BG - ER'!F14-'BG - ER'!E14) -> 0 | E10: =-('BG - ER'!G14-'BG - ER'!F14) -> 0
A11: Inventarios | B11: =-('BG - ER'!D15-'BG - ER'!C15) -> -2525658 | C11: =-('BG - ER'!E15-'BG - ER'!D15) -> -21341071 | D11: =-('BG - ER'!F15-'BG - ER'!E15) -> -3126239 | E11: =-('BG - ER'!G15-'BG - ER'!F15) -> 9479524
A12: Deudores comerciales | B12: ='BG - ER'!D29-'BG - ER'!C29 -> -40150886 | C12: ='BG - ER'!E29-'BG - ER'!D29 -> -7081799 | D12: ='BG - ER'!F29-'BG - ER'!E29 -> 22001532 | E12: ='BG - ER'!G29-'BG - ER'!F29 -> 17703168
A13: Deudas diversas | B13: ='BG - ER'!D30-'BG - ER'!C30 -> 22913 | C13: ='BG - ER'!E30-'BG - ER'!D30 -> 104437 | D13: ='BG - ER'!F30-'BG - ER'!E30 -> 546297 | E13: ='BG - ER'!G30-'BG - ER'!F30 -> 2984667
A14: Impuestos y cargas sociales por pagar | B14: ='BG - ER'!D33-'BG - ER'!C33 -> 8224236 | C14: ='BG - ER'!E33-'BG - ER'!D33 -> 11003754 | D14: ='BG - ER'!F33-'BG - ER'!E33 -> -22674223 | E14: ='BG - ER'!G33-'BG - ER'!F33 -> -3679449
A15: Deudas comerciales | B15: =('BG - ER'!D37-'BG - ER'!C37) -> 0 | C15: =('BG - ER'!E37-'BG - ER'!D37) -> 1168076 | D15: =('BG - ER'!F37-'BG - ER'!E37) -> -1168076 | E15: =('BG - ER'!G37-'BG - ER'!F37) -> 0
A16: Previcion para indemnizaciones | B16: ='BG - ER'!D40-'BG - ER'!C40 -> 4744810 | C16: ='BG - ER'!E40-'BG - ER'!D40 -> -2912575 | D16: ='BG - ER'!F40-'BG - ER'!E40 -> 2072824 | E16: ='BG - ER'!G40-'BG - ER'!F40 -> 1043045
A17: FEO | B17: =SUM(B4:B16) -> 137912523 | C17: =SUM(C4:C16) -> 97287614 | D17: =SUM(D4:D16) -> 58979989 | E17: =SUM(E4:E16) -> -6286192
A19: Inversiones temporarias | B19: ='BG - ER'!D7-'BG - ER'!C7 -> 0 | C19: ='BG - ER'!E7-'BG - ER'!D7 -> 7140830 | D19: ='BG - ER'!F7-'BG - ER'!E7 -> 78383053 | E19: ='BG - ER'!G7-'BG - ER'!F7 -> 68117191
A20: Inversiones permanente | B20: ='BG - ER'!D16-'BG - ER'!C16 -> 808819 | C20: ='BG - ER'!E16-'BG - ER'!D16 -> 5093868 | D20: ='BG - ER'!F16-'BG - ER'!E16 -> 115730420 | E20: ='BG - ER'!G16-'BG - ER'!F16 -> -59668587
A21: Activo Fijo Bruto | B21: ='BG - ER'!D18-'BG - ER'!C18 -> 39908352 | C21: ='BG - ER'!E18-'BG - ER'!D18 -> 62152908 | D21: ='BG - ER'!F18-'BG - ER'!E18 -> 63496572 | E21: ='BG - ER'!G18-'BG - ER'!F18 -> 57187918
A22: Otros activos | B22: ='BG - ER'!D20-'BG - ER'!C20 -> 1582006 | C22: ='BG - ER'!E20-'BG - ER'!D20 -> -1469520 | D22: ='BG - ER'!F20-'BG - ER'!E20 -> -2006931 | E22: ='BG - ER'!G20-'BG - ER'!F20 -> -152457
B23: =SUM(B19:B22) -> 42299177 | C23: =SUM(C19:C22) -> 72918086 | D23: =SUM(D19:D22) -> 255603114 | E23: =SUM(E19:E22) -> 65484065
A25: Obligaciones financieras | B25: ='BG - ER'!D31-'BG - ER'!C31 -> 8865593 | C25: ='BG - ER'!E31-'BG - ER'!D31 -> -3855863 | D25: ='BG - ER'!F31-'BG - ER'!E31 -> 9042440 | E25: ='BG - ER'!G31-'BG - ER'!F31 -> 20702962
A26: Bonos y pagares bursatiles | B26: ='BG - ER'!D32-'BG - ER'!C32 -> -32967 | C26: ='BG - ER'!E32-'BG - ER'!D32 -> 5052916 | D26: ='BG - ER'!F32-'BG - ER'!E32 -> -991944 | E26: ='BG - ER'!G32-'BG - ER'!F32 -> 1232544
A27: Dividendos por pagar | B27: ='BG - ER'!D34-'BG - ER'!C34 -> 0 | C27: ='BG - ER'!E34-'BG - ER'!D34 -> 0 | D27: ='BG - ER'!F34-'BG - ER'!E34 -> 10910000 | E27: ='BG - ER'!G34-'BG - ER'!F34 -> -10910000
A28: Obligaciones financieras | B28: ='BG - ER'!D38-'BG - ER'!C38 -> 17186905 | C28: ='BG - ER'!E38-'BG - ER'!D38 -> 8156066 | D28: ='BG - ER'!F38-'BG - ER'!E38 -> 69439233 | E28: ='BG - ER'!G38-'BG - ER'!F38 -> 11379232
A29: Bonos y pagares bursatiles | B29: ='BG - ER'!D39-'BG - ER'!C39 -> -8827136 | C29: ='BG - ER'!E39-'BG - ER'!D39 -> -13928352 | D29: ='BG - ER'!F39-'BG - ER'!E39 -> -13098024 | E29: ='BG - ER'!G39-'BG - ER'!F39 -> -14927808
A30: MENOS: INTERESES | B30: =-('BG - ER'!D78) -> -13048454 | C30: =-('BG - ER'!E78) -> -10320151 | D30: =-('BG - ER'!F78) -> -15295929 | E30: =-('BG - ER'!G78) -> -29530033
B31: =SUM(B25:B30) -> 4143941 | C31: =SUM(C25:C30) -> -14895384 | D31: =SUM(D25:D30) -> 60005776 | E31: =SUM(E25:E30) -> -22053103

Sheet NOTAS
A2: NOTAS A LOS ESTADOS FINANCIEROS
A3: BALANCE GENERAL
A5: NOTA 3 - DISPONIBILIDADES
B6: 2020 | C6: 2021 | D6: 2022 | E6: 2023 | F6: 2024
A7: Efectivo en caja | B7: 1235090 | C7: 1961825 | D7: 21134602 | E7: 29270 | F7: 319001
A8: Efectivo en bancos | B8: 188079196 | C8: 294051000 | D8: 318051722 | E8: 144032266 | F8: 115819956
A9: Total | B9: =B7+B8 -> 189314286 | C9: =C7+C8 -> 296012825 | D9: =D7+D8 -> 339186324 | E9: =E7+E8 -> 144061536 | F9: =F7+F8 -> 116138957
A11: NOTA 4 - CUENTAS POR COBRAR COMERCIALES
B12: 2020 | C12: 2021 | D12: 2022 | E12: 2023 | F12: 2024
A13: CORRIENTE
A14: CUENTAS A COBRAR EN Bolivia | B14: 154522479 | C14: 72550560 | D14: 79108283 | E14: 96289281 | F14: 133062154
A15: Cheques rechazados | B15: 14754 | C15: 52929 | D15: 61464 | E15: 98282 | F15: 61081
A16: Cobradores móviles | B16: 2427 | C16: 0 | D16: 0 | E16: 0 | F16: 0
A17: Cuentas por cobrar del exterior | B17: 472693 | C17: 888580 | D17: 1337142 | E17: 1814856 | F17: 2251800
A18: Previsión para deudores incobrables | B18: 0 | C18: 0 | D18: 0 | E18: 0 | F18: 5369084
A19: Total | B19: =SUM(B14:B18) -> 155012353 | C19: =SUM(C14:C18) -> 73492069 | D19: =SUM(D14:D18) -> 80506889 | E19: =SUM(E14:E18) -> 98202419 | F19: =F14+F15+F17-F18 -> 130005951
A21: NO CORRIENTE
A22: Cuentas a cobrar en Bolivia | B22: 5257719 | C22: 3860421 | D22: 2215259 | E22: 2227665 | F22: 0
A23: Cuentas por cobrar del exterior | B23: 353422 | C23: 353422 | D23: 353422 | E23: 353422 | F23: 0
A24: Revición para deudas incobrables | B24: 5611141 | C24: 4213843 | D24: 2568681 | E24: 2581087 | F24: 0
A25: Total | B25: 0 | C25: 0 | D25: 0 | E25: 0 | F25: 0
A26: Total cuentas por cobrar comerciales | B26: 151012353 | C26: 73492069 | D26: =D19 -> 80506889 | E26: =E19 -> 98202419 | F26: =F19 -> 130005951
A28: NOTA 5 - OTRAS CUENTAS POR COBRAR
B29: 2020 | C29: 2021 | D29: 2022 | E29: 2023 | F29: 2024
A30: Fondos cedidos BNB Valores | B30: 3489448 | C30: 3487893 | D30: 5096794 | E30: 6444478 | F30: 0
A31: Cuentas por cobrar accionistas | B31: 0 | C31: 3720000 | D31: 0 | E31: 0 | F31: 0
A32: Otras cuentas por cobrar | B32: 510456 | C32: 1172315 | D32: 305210 | E32: 682158 | F32: 846468
A33: Total | B33: =SUM(B30:B32) -> 3999904 | C33: =SUM(C30:C32) -> 8380208 | D33: =SUM(D30:D32) -> 5402004 | E33: =SUM(E30:E32) -> 7126636 | F33: =SUM(F30:F32) -> 846468
A35: NOTA 6 - PAGOS ANTICIPADOS
B36: 2020 | C36: 2021 | D36: 2022 | E36: 2023 | F36: 2024
A37: Anticipos al personal | B37: 476602 | C37: 368820 | D37: 498330 | E37: 308321 | F37: 655581
A38: Anticipos a proveedores | B38: 3307489 | C38: 8091356 | D38: 9884908 | E38: 7268671 | F38: 5829587
A39: Anticipos de aportes Instituto Bolivianos de Nefrología | B39: 2316173 | C39: 2316174 | D39: 176226 | E39: 176226 | F39: 176226
A40: IVA diferido | B40: 0 | C40: 30775 | D40: 20226 | E40: 9277 | F40: 0
A41: Anticipo impuestos a las transacciones | B41: 17652998 | C41: 32030264 | D41: 35566845 | E41: 25049617 | F41: 14840439
A42: Previsión por incobrabilidad de aportes por capitalizar | B42: 0 | C42: 0 | D42: 0 | E42: 0 | F42: 176226
A43: Total | B43: =SUM(B37:B41) -> 23753262 | C43: =SUM(C37:C41) -> 42837389 | D43: =SUM(D37:D41) -> 46146535 | E43: =SUM(E37:E41) -> 32812112 | F43: =F37+F38+F39+F40+F41+-F42 -> 21325607
A45: NOTA 7 - INVENTARIOS
B46: 2020 | D46: 2021 | F46: 2022 | H46: 2023 | J46: 2024
B47: Corriente | C47: No corriente | D47: Corriente | E47: No corriente | F47: Corriente | G47: No corriente | H47: Corriente | I47: No corriente | J47: Corriente | K47: No corriente
...

Sheet LIQUIDEZ
B2: LIQUIDEZ CORRIENTE
B4: DETALLE | C4: 2020 | D4: 2021 | E4: 2022 | F4: 2023 | G4: 2024
B5: LC=AC/PC | C5: ='BG - ER'!C12/'BG - ER'!C35 -> 3.9327626 | D5: ='BG - ER'!D12/'BG - ER'!D35 -> 5.0698992 | E5: ='BG - ER'!E12/'BG - ER'!E35 -> 4.8577526 | F5: ='BG - ER'!F12/'BG - ER'!F35 -> 3.8901448 | G5: ='BG - ER'!G12/'BG - ER'!G35 -> 3.7018462
B6: LC promedio | C6: =AVERAGE($C$5:$G$5) -> 4.2904811 | D6: =AVERAGE($C$5:$G$5) -> 4.2904811 | E6: =AVERAGE($C$5:$G$5) -> 4.2904811 | F6: =AVERAGE($C$5:$G$5) -> 4.2904811 | G6: =AVERAGE($C$5:$G$5) -> 4.2904811
I10: La empresa muestra una liquidez que puede cubrir sus obigaciones tanto a corto y a largo plazo, pero se muestra una caida entre 5 gestiones: en 2020 con 5,52 y al 2024 con 3,70
B25: LIQUIDEZ ACIDA | L25: EN LA GESTION 2024, LA EMPRESA PRESENTA UN INDICE DE LIQUIDEZ DE 3.52, LO QUE INDICA QUE POR CADA BOLIVIANO DE DEUDA A CORTO PLAZO DISPONE DE 3.52 BS EN ACTIVOS LIQUIDOS PARA HACER FRENTE A SUS OBLIGACIONES INMEDIATAS. SE OBSERVA EN LA GESTION 2021 Y 2022 QUE LA LIQUIDEZ ACIDA FUE DE 4.92 Y 4.56 LO QUE REFLEJA QUE EN ESOS PERIODOS EXISTIA UNA MAYOR CAPACIDAD DE PAGO.
B27: DETALLE | C27: 2020 | D27: 2021 | E27: 2022 | F27: 2023 | G27: 2024
B28: LA=(AC-INV)/PC | C28: =('BG - ER'!C12-'BG - ER'!C15)/'BG - ER'!C35 -> 3.8231999 | D28: =('BG - ER'!D12-'BG - ER'!D15)/'BG - ER'!D35 -> 4.9226298 | E28: =('BG - ER'!E12-'BG - ER'!E15)/'BG - ER'!E35 -> 4.5627411 | F28: =('BG - ER'!F12-'BG - ER'!F15)/'BG - ER'!F35 -> 3.6105059 | G28: =('BG - ER'!G12-'BG - ER'!G15)/'BG - ER'!G35 -> 3.5152649
B29: LA promedio | C29: =AVERAGE($C$28:$G$28) -> 4.0868683 | D29: =AVERAGE($C$28:$G$28) -> 4.0868683 | E29: =AVERAGE($C$28:$G$28) -> 4.0868683 | F29: =AVERAGE($C$28:$G$28) -> 4.0868683 | G29: =AVERAGE($C$28:$G$28) -> 4.0868683
J34: =CORREL(C5:G5,C28:G28) -> 0.99151594
B48: LIQUIDEZ INMEDIATA
B50: DETALLE | C50: 2020 | D50: 2021 | E50: 2022 | F50: 2023 | G50: 2024 | J50: NOTA: Se pone % si es menor a 1
B51: LI=DISPO/PC | C51: ='BG - ER'!C6/'BG - ER'!C35 -> 1.2051395 | D51: ='BG - ER'!D6/'BG - ER'!D35 -> 2.2087543 | E51: ='BG - ER'!E6/'BG - ER'!E35 -> 2.2995045 | F51: ='BG - ER'!F6/'BG - ER'!F35 -> 0.91134613 | G51: ='BG - ER'!G6/'BG - ER'!G35 -> 0.62403583
B52: LI promedio | C52: =AVERAGE($C$51:$G$51) -> 1.449756 | D52: =AVERAGE($C$51:$G$51) -> 1.449756 | E52: =AVERAGE($C$51:$G$51) -> 1.449756 | F52: =AVERAGE($C$51:$G$51) -> 1.449756 | G52: =AVERAGE($C$51:$G$51) -> 1.449756
I54: La empresa Drogueria Inti S.A. es capaz de cubrir el 0,62 de sus deudas a corto plazo si tuviera que liquidarse con su efectivo liquido, siendo este el mas bajo ya que en la gestion 2023 fue capaz de cubrir sus deudas a corto plazo en un 0,91 , sufriendo un decaimiento en comparacion a las gestiones anteriores ya que en 2022 era capaz de cubrir sus deudas corrientes 2.30 veces, en 2021 cubriria 2.21 veces y en la gestion 2020 cubriria en 1.21 vece sus deudas corrientes

Sheet DEUDA
B2: INDICE DE DEUDA
B3: DETALLE | C3: 2020 | D3: 2021 | E3: 2022 | F3: 2023 | G3: 2024
B4: ID=PT/AT | C4: ='BG - ER'!C43/'BG - ER'!C23 -> 0.37021319 | D4: ='BG - ER'!D43/'BG - ER'!D23 -> 0.32696194 | E4: ='BG - ER'!E43/'BG - ER'!E23 -> 0.30418578 | F4: ='BG - ER'!F43/'BG - ER'!F23 -> 0.34444989 | G4: ='BG - ER'!G43/'BG - ER'!G23 -> 0.34794999
B5: ID promedio | C5: =AVERAGE($C$4:$G$4) -> 0.33875216 | D5: =AVERAGE($C$4:$G$4) -> 0.33875216 | E5: =AVERAGE($C$4:$G$4) -> 0.33875216 | F5: =AVERAGE($C$4:$G$4) -> 0.33875216 | G5: =AVERAGE($C$4:$G$4) -> 0.33875216 | I5: En la empresa Droguería INTI SA, se observa que en la gestión 2020 la compañía mantenía un bajo nivel de compromisos con terceros, representando solo el 37% de sus recursos, pero siendo el mas alto de las gestiones registadas, en los siguientes 2 años este porcentaje ha ido disminuyendo hasta llegar al 30% en 2022. Sin embargo en los ultimos dos años (2023 y 2024) ha ido subiendo quedando con un 35% en la ultima gestión lo que podría representar un riesgo para la empresa si este porcentaje llegará a subir más en las proximas gestiones.
I18: PARAMETROS
I19: <50% | J19: QUE LA EMPRESA NO TIENE COMPROMETIDA SUS RECURSOS CON TERCERAS PERSONAS
I20: >50% | J20: QUE LA EMPRESA TIENE COMPROMETIDO SUS RECURSOS CON TERCERAS PERSONAS, RIESGO DE QUIEBRA
B25: INDICE DE COBERTURA DE INTERES
B26: DETALLE | C26: 2020 | D26: 2021 | E26: 2022 | F26: 2023 | G26: 2024 | J26: acuden a la caja que tienen acumulada para pagar los interes de ese año si es que no me alcanza con el que tengo. Si no pago se acumula.
B27: ICI= RO/Intereses | C27: ='BG - ER'!C69/'BG - ER'!C75 -> 3.1882821 | D27: ='BG - ER'!D69/'BG - ER'!D75 -> 5.3027384 | E27: ='BG - ER'!E69/'BG - ER'!E75 -> 5.8100342 | F27: ='BG - ER'!F69/'BG - ER'!F75 -> 9.8149675 | G27: ='BG - ER'!G69/'BG - ER'!G75 -> 3.8813285
B28: ICI promedio | C28: =AVERAGE($C$27:$G$27) -> 5.5994701 | D28: =AVERAGE($C$27:$G$27) -> 5.5994701 | E28: =AVERAGE($C$27:$G$27) -> 5.5994701 | F28: =AVERAGE($C$27:$G$27) -> 5.5994701 | G28: =AVERAGE($C$27:$G$27) -> 5.5994701
I29: Cuantas veces puede pagar los intereses la empresa con su resultado operativo | Q29: La empresa droguería INTI, en la gestión 2024 presnta un índice de 3,88 puntos. Em 2023, el índice aumenta en 9,81 puntos. En 2022, el índice disminuye en 5,81 puntos. El 2021 disminuye un poco en 5,30 puntos. Por último, en 2020 se llegó a tener un índice de 3,19 puntos, siendo el índice de cobertura de interés más bajo en los últimos cinco años.
I30: siclico= que sube y baja, comportamiento de una onda
I31: aumenta deuda, mejora covertura
I32: si baja la deuda, baja la cobertura y esta super mal
I33: si la empresa tienen un indice de deuda mas elevado que pasaria con el indice de cobertura de interes normalmente
I34: R: la cobertura baja normalmente, lo ideal es que suban los 2
I36: si baja mi indice de deuda, mejor cobertura
I39: =CORREL(C4:G4,C27:G27) -> -0.27994889 | J39: Correlación debil negativo
J40: Si es positivo esta aumentando la deuda y esta aumentado la cobertura
B47: Lo minimo que puede estar es 1, si es menor que 1 no puede pagar sus interes con sus resultados operativos
B48: Si se esta apegando mucho el 1, se esta acercando al riesgo financiero. Lo ideal es que nos alejemos del 1
B49: Si tengo muchas dedudas no tengo riesgo financiero si es que tengo mejor covertura (hay que ver la capacidad de pago)
B50: Aumenta el riesgo si baja la cobertura | N50: La empresa Drogueria Inti en la gestion 2024 solvento sus operaciones con un 44% de deuda corriente al igual que en la gestion 2022, mientras que en la gestion 2023 presento un pico menor de endeudamiento a corto plazo con un 40% al igual que la gestion 2021 que presento un 42% mientras que en la gestion 2020 en medio de la pandemia tuvo el pico de endeudamiento mas alto a corto plazo con un 48%
B52: INDICE DE CALIDAD DE DEUDA
B53: DETALLE | C53: 2020 | D53: 2021 | E53: 2022 | F53: 2023 | G53: 2024
B54: ICD=PC/PT | C54: ='BG - ER'!C35/'BG - ER'!C43 -> 0.47762472 | D54: ='BG - ER'!D35/'BG - ER'!D43 -> 0.42021134 | E54: ='BG - ER'!E35/'BG - ER'!E43 -> 0.43975151 | F54: ='BG - ER'!F35/'BG - ER'!F43 -> 0.40251801 | G54: ='BG - ER'!G35/'BG - ER'!G43 -> 0.44497701
B55: ICD PROMEDIO | C55: =AVERAGE($C$54:$G$54) -> 0.43701652 | D55: =AVERAGE($C$54:$G$54) -> 0.43701652 | E55: =AVERAGE($C$54:$G$54) -> 0.43701652 | F55: =AVERAGE($C$54:$G$54) -> 0.43701652 | G55: =AVERAGE($C$54:$G$54) -> 0.43701652
I61: =CORREL(C54:G54,LIQUIDEZ!C5:G5) -> -0.23984712 | J61: ESTA BIEN, PERO SU CORRELACION ES DEBIL
I63: si sale -1 esta perfectamente negativa
I64: correlacion inversa
I65: si sale positivo quiere decir que aumenta la deuda a corto plazo, esa empresa tiene mas liquidez
I66: la liquidez no se encuentra muy clara o explicado por la composicion de deuda corto largo
B74: menos concentracion de deuda
B75: si una empresa tiene menos concentracion de deuda a corto plazo, que pasa con la liquidez fuente
B76: R: deberia de bajar
B77: la liquidez se estresa tiene mucha deuda

Sheet EFICIENCIA O ACTIVIDAD
B3: ROTACIÓN DE ACTIVO TOTAL
B4: Detalle | C4: 2020 | D4: 2021 | E4: 2022 | F4: 2023 | G4: 2024
B5: Rat= V/AT | C5: ='BG - ER'!C54/'BG - ER'!C23 -> 0.80855516 | D5: ='BG - ER'!D54/'BG - ER'!D23 -> 0.76212325 | E5: ='BG - ER'!E54/'BG - ER'!E23 -> 0.74061228 | F5: ='BG - ER'!F54/'BG - ER'!F23 -> 0.66962038 | G5: ='BG - ER'!G54/'BG - ER'!G23 -> 0.67026729
B6: Promedio | C6: =AVERAGE($C$5:$G$5) -> 0.73023567 | D6: =AVERAGE($C$5:$G$5) -> 0.73023567 | E6: =AVERAGE($C$5:$G$5) -> 0.73023567 | F6: =AVERAGE($C$5:$G$5) -> 0.73023567 | G6: =AVERAGE($C$5:$G$5) -> 0.73023567
I12: Por cada bs invertido en los activo, ese activo me genera 0,67 activo en ventas
I13: mientras mas elevado sea este numero es mejor, si la rotacion de activo aumenta
I14: la rentabilidad deberia aumentar, se mueven en el mismo sentido
B24: Es decreciente entonces la rentabilidad esta disminuyendo de alguna manera
B27: PERIODO PROMEDIO DE COBRO
B28: Detalle | C28: 2020 | D28: 2021 | E28: 2022 | F28: 2023 | G28: 2024
B29: PPC= 360/(V/C*C) | C29: =360/('BG - ER'!C54/'BG - ER'!C8) -> 77.687612 | D29: =360/('BG - ER'!D54/'BG - ER'!D8) -> 35.589314 | E29: =360/('BG - ER'!E54/'BG - ER'!E8) -> 37.594332 | F29: =360/('BG - ER'!F54/'BG - ER'!F8) -> 46.306579 | G29: =360/('BG - ER'!G54/'BG - ER'!G8) -> 58.090312
B30: PPCC promedio | C30: =AVERAGE($C$29:$G$29) -> 51.05363 | D30: =AVERAGE($C$29:$G$29) -> 51.05363 | E30: =AVERAGE($C$29:$G$29) -> 51.05363 | F30: =AVERAGE($C$29:$G$29) -> 51.05363 | G30: =AVERAGE($C$29:$G$29) -> 51.05363
I39: Cuantos dias de promerio, la empresa recupera sus ventas a credito
I40: las cifras se leen en dias
I41: que es bueno para el flujo de caja? Que sea menos dias
I42: si una empresa demora poco en cobrar es mejor para la caja, genera mas flujo
I43: si demora en cobrar se afecta el flujo, la inversion
I44: por que una empresa aumenta su tiempo de cobro? Aumenta la venta de credito aumenta los dias,
I45: si la empresa hubiera flexibilizado sus politicas de credito
I46: exista una politica de credito y ignoren esas politicas
B48: Es eficiente en las cuentas por cobrar? NO
B49: periodo promedio de cobro es depende del ciclo del cliente
B50: un ciclo de un negocio ganadero no es mensual, sino trimestral
B53: PERIODO PROMEDIO DE INVENTARIO
B54: Detalle | C54: 2020 | D54: 2021 | E54: 2022 | F54: 2023 | G54: 2024
B55: PPI=360/(CV/INV) | C55: =360/('BG - ER'!C56/'BG - ER'!C11) -> 285.99389 | D55: =360/('BG - ER'!D56/'BG - ER'!D11) -> 316.59967 | E55: =360/('BG - ER'!E56/'BG - ER'!E11) -> 265.68875 | F55: =360/('BG - ER'!F56/'BG - ER'!F11) -> 294.00492 | G55: =360/('BG - ER'!G56/'BG - ER'!G11) -> 305.03304
B56: PPI promedio | C56: =AVERAGE($C$55:$G$55) -> 293.46405 | D56: =AVERAGE($C$55:$G$55) -> 293.46405 | E56: =AVERAGE($C$55:$G$55) -> 293.46405 | F56: =AVERAGE($C$55:$G$55) -> 293.46405 | G56: =AVERAGE($C$55:$G$55) -> 293.46405
I65: Cuanto tiempo la empresa demora en vender su inventario
I66: el numero sea decreciente, ya que se lee las cifras en dias
I67: si la empresa demora en el periodo se afecta el flujo, afecta la rentabilidad e igual que el dinero no esta en movimiento
I69: periodo de inventaro de una empresa de pan deberia ser 1 dia
I70: por que se ve eso? Puede ser interno o externo, externo que paso en el macro entorno si sea el politico, social o economico
I71: no roten como deberian
I72: micro interno puede ser que la empresa lo hace bien, pero la competencia lo hace mejor
B75: PERIODO PROMEDIO DE PAGO
B76: Detalle | C76: 2020 | D76: 2021 | E76: 2022 | F76: 2023 | G76: 2024
B77: PPP=360/CV/C*P) | C77: =360/('BG - ER'!C56/'BG - ER'!C29) -> 116.42112 | D77: =360/('BG - ER'!D56/'BG - ER'!D29) -> 73.263712 | E77: =360/('BG - ER'!E56/'BG - ER'!E29) -> 64.631198 | F77: =360/('BG - ER'!F56/'BG - ER'!F29) -> 88.950854 | G77: =360/('BG - ER'!G56/'BG - ER'!G29) -> 105.67582
B78: PPP promedio | C78: =AVERAGE($C$77:$G$77) -> 89.78854 | D78: =AVERAGE($C$77:$G$77) -> 89.78854 | E78: =AVERAGE($C$77:$G$77) -> 89.78854 | F78: =AVERAGE($C$77:$G$77) -> 89.78854 | G78: =AVERAGE($C$77:$G$77) -> 89.78854
I86: Cuanto tiempo demora en pagar a sus proveedores
I87: deberia de demorar en pagar mucho mejor, pero deberia negociar
...

Sheet RENTABILIDAD
B2: ANALISIS DE MARGENES
B4: MARGEN BRUTO
B5: Detalle | C5: 2020 | D5: 2021 | E5: 2022 | F5: 2023 | G5: 2024
B6: MB=UB/V | C6: ='BG - ER'!C61/'BG - ER'!C54 -> 0.49853245 | D6: ='BG - ER'!D61/'BG - ER'!D54 -> 0.52869884 | E6: ='BG - ER'!E61/'BG - ER'!E54 -> 0.52029449 | F6: ='BG - ER'!F61/'BG - ER'!F54 -> 0.50318336 | G6: ='BG - ER'!G61/'BG - ER'!G54 -> 0.51687005
B7: MB promedio | C7: =AVERAGE($C$6:$G$6) -> 0.51351584 | D7: =AVERAGE($C$6:$G$6) -> 0.51351584 | E7: =AVERAGE($C$6:$G$6) -> 0.51351584 | F7: =AVERAGE($C$6:$G$6) -> 0.51351584 | G7: =AVERAGE($C$6:$G$6) -> 0.51351584
I15: Es bueno que crezca
I16: si baja
I18: Margen es lo que me queda
I19: bruto es lo que le queda a la empresa despues de cubrir sus costos de ventas
I20: de cada 100 que vendes paga su costos y se queda con 52%
B26: MARGEN OPERATIVO
B27: Detalle | C27: 2020 | D27: 2021 | E27: 2022 | F27: 2023 | G27: 2024
B28: MO= RO/V | C28: ='BG - ER'!C69/'BG - ER'!C54 -> 0.064199906 | D28: ='BG - ER'!D69/'BG - ER'!D54 -> 0.11968176 | E28: ='BG - ER'!E69/'BG - ER'!E54 -> 0.10346725 | F28: ='BG - ER'!F69/'BG - ER'!F54 -> 0.10522576 | G28: ='BG - ER'!G69/'BG - ER'!G54 -> 0.095139134
B29: MO promedio | C29: =AVERAGE($C$28:$G$28) -> 0.097542762 | D29: =AVERAGE($C$28:$G$28) -> 0.097542762 | E29: =AVERAGE($C$28:$G$28) -> 0.097542762 | F29: =AVERAGE($C$28:$G$28) -> 0.097542762 | G29: =AVERAGE($C$28:$G$28) -> 0.097542762
I35: DESPUES DE HABER PAGADO EL COSTO DE VENTA Y LOS GASTOS OPERATIVOS TIENENUNA GANANCIA DE 10% 2024
I36: SI BAJA EL MARGEN BRUTO, NO NECESARIAMENTE TIENE QUE BAJAR EL MARGEN OPERATIVO
B48: MARGEN NETO
B49: Detalle | C49: 2020 | D49: 2021 | E49: 2022 | F49: 2023 | G49: 2024 | I49: EL MARGEN NETO ES DESPUES DE PAGAR EL COSTO DE VENTA, GASTO OPE, INTERES, IMPUESTO Y LO QUE SOBRA ES PARA EL EMPRESARIO
B50: MN=UN/V | C50: ='BG - ER'!C84/'BG - ER'!C54 -> 0.061600895 | D50: ='BG - ER'!D84/'BG - ER'!D54 -> 0.13378798 | E50: ='BG - ER'!E84/'BG - ER'!E54 -> 0.12314218 | F50: ='BG - ER'!F84/'BG - ER'!F54 -> 0.10082279 | G50: ='BG - ER'!G84/'BG - ER'!G54 -> 0.09249178 | I50: MIENTRAS MAS SEA EL MARGEN NETO MEJOR ES PARA EL EMPRESARIO
B51: MN promedio | C51: =AVERAGE($C$50:$G$50) -> 0.10236913 | D51: =AVERAGE($C$50:$G$50) -> 0.10236913 | E51: =AVERAGE($C$50:$G$50) -> 0.10236913 | F51: =AVERAGE($C$50:$G$50) -> 0.10236913 | G51: =AVERAGE($C$50:$G$50) -> 0.10236913 | I51: AL MARGEN NETO LE AFECTA LA DEUDA
I52: CUANDO CAE EL MARGEN EL INDICE DE DEUDA HA AUMENTADO
I53: SI PAGAMOS MAS INTERESES NOS COMEMOS EL MARGEN NETO
I55: lo que nos queda depsues de pagar la deuda
B71: RENTABILIDAD SOBRE LOS ACTIVOS
B72: Detalle | C72: 2020 | D72: 2021 | E72: 2022 | F72: 2023 | G72: 2024
B73: ROA= RN/AT | C73: ='BG - ER'!C84/'BG - ER'!C23 -> 0.049807721 | D73: ='BG - ER'!D84/'BG - ER'!D23 -> 0.10196293 | E73: ='BG - ER'!E84/'BG - ER'!E23 -> 0.091200611 | F73: ='BG - ER'!F84/'BG - ER'!F23 -> 0.067512994 | G73: ='BG - ER'!G84/'BG - ER'!G23 -> 0.061994215
B74: ROA promedio | C74: =AVERAGE($C$73:$G$73) -> 0.074495694 | D74: =AVERAGE($C$73:$G$73) -> 0.074495694 | E74: =AVERAGE($C$73:$G$73) -> 0.074495694 | F74: =AVERAGE($C$73:$G$73) -> 0.074495694 | G74: =AVERAGE($C$73:$G$73) -> 0.074495694
I83: Es rentable cuando el ROA es positivo
I84: POR CADA BOLIVIANA QUE INVIERTE TIENE UNA GANANCIA DE 6%
I85: mientras mas arto, mejor
I86: es o no es rentableen tanto a sus activos
B93: RENTABILIDAD SOBRE EL PATRIMONIO
B94: Detalle | C94: 2020 | D94: 2021 | E94: 2022 | F94: 2023 | G94: 2024
B95: ROE=RN/PT | C95: ='BG - ER'!C84/'BG - ER'!C45 -> 0.079086638 | D95: ='BG - ER'!D84/'BG - ER'!D45 -> 0.15149653 | E95: ='BG - ER'!E84/'BG - ER'!E45 -> 0.13107035 | F95: ='BG - ER'!F84/'BG - ER'!F45 -> 0.10298678 | G95: ='BG - ER'!G84/'BG - ER'!G45 -> 0.095073676
B96: ROE promedio | C96: =AVERAGE($C$95:$G$95) -> 0.11194279 | D96: =AVERAGE($C$95:$G$95) -> 0.11194279 | E96: =AVERAGE($C$95:$G$95) -> 0.11194279 | F96: =AVERAGE($C$95:$G$95) -> 0.11194279 | G96: =AVERAGE($C$95:$G$95) -> 0.11194279
I108: cuanto es la rentabilidad del dueño
I109: por cada boliviano que invierte el dueño, va a ganar 10% (ganancia)
I110: la rentabilidad siempre mide, entre un resultado y un esfuerzo
I111: resultado sobre esfuerzo, esfuerzo del dueño (patrimnio)
I112: siempre la rentabilidad tiene que ser un cociente
...

Sheet DUPONT
B2: ANALISIS DUPONT
B3: Detalle | C3: 2020 | D3: 2021 | E3: 2022 | F3: 2023 | G3: 2024 | I3: es una herramienta que respuesta la pregunta: LA RENTABILIDAD DE DONDE VIENE
A4: margen | B4: MN=RN/V | C4: ='BG - ER'!C84/'BG - ER'!C54 -> 0.061600895 | D4: ='BG - ER'!D84/'BG - ER'!D54 -> 0.13378798 | E4: ='BG - ER'!E84/'BG - ER'!E54 -> 0.12314218 | F4: ='BG - ER'!F84/'BG - ER'!F54 -> 0.10082279 | G4: ='BG - ER'!G84/'BG - ER'!G54 -> 0.09249178 | I4: UNA EMPRESA PUEDE SER RENTABLE
A5: eficiencia | B5: RAT=V/AT | C5: ='BG - ER'!C54/'BG - ER'!C23 -> 0.80855516 | D5: ='BG - ER'!D54/'BG - ER'!D23 -> 0.76212325 | E5: ='BG - ER'!E54/'BG - ER'!E23 -> 0.74061228 | F5: ='BG - ER'!F54/'BG - ER'!F23 -> 0.66962038 | G5: ='BG - ER'!G54/'BG - ER'!G23 -> 0.67026729
B6: ROA=RN/AT | C6: =C4*C5 -> 0.049807721 | D6: =D4*D5 -> 0.10196293 | E6: =E4*E5 -> 0.091200611 | F6: =F4*F5 -> 0.067512994 | G6: =G4*G5 -> 0.061994215 | I6: QUE QUEDA CON ESA MULTIPLICACION
A7: apalancamiento | B7: Multiplicador del Aplancamiento= AT/Patri. | C7: ='BG - ER'!C23/'BG - ER'!C45 -> 1.5878389 | D7: ='BG - ER'!D23/'BG - ER'!D45 -> 1.4858001 | E7: ='BG - ER'!E23/'BG - ER'!E45 -> 1.4371652 | F7: ='BG - ER'!F23/'BG - ER'!F45 -> 1.5254364 | G7: ='BG - ER'!G23/'BG - ER'!G45 -> 1.5335895 | I7: la rentabilidad puede venir de 2 factores importantes: el margen y la rotacion
B8: ROE=RN/AT | C8: =C6*C7 -> 0.079086638 | D8: =D6*D7 -> 0.15149653 | E8: =E6*E7 -> 0.13107035 | F8: =F6*F7 -> 0.10298678 | G8: =G6*G7 -> 0.095073676 | I8: rotacion=mucho volumen de ventas
I9: ej: las comidas afuera de las uni publicas
B10: La empresa Drogueria Inti S.A. en la gestión 2024 la rentabilidad disminuyo con respecto a sus anteriores gestiones, debido a que el margen disminuyo a un 9,25% a pesar de que hubo un incremento en las ventas y en los otros ingresos, y el apalancamiento se mantuvo. La empresa presento una administración ineficiente ya que los gastos de comercialización y financieros fueron el factor crucial para que el margen disminuyera ya que paso de -8,65 paso a 14,63 afectando un 34,58% al margen | I10: ej: un restaurante del ventura
I12: estrategias genericas de dupont
I13: estrategia de liderazgo en costos y estrategia de diferenciacion: apunta al margen
I14: estrategia liderazgo en costos: costos bajos, precio bajos y apuestas a volumen
I16: cuando expliquemos el ROA tienen en explicarlo apoyarlo al dupont
I17: porque sube o porque baja
B18: si el m. de apalancamiento es 1 no tiene pasivo
B19: mientras ese numero sea mas grande tiene mas deuda | I19: afectan la rentabilidad de una empresa es:
B20: si tiene 2 significa que la empresa tiene mitad deuda mitad patrimnio | I20: margen, eficiencia y apalancamiento
B21: la empresa tiene mas deuda que patrimnio
B23: la fiderenia del roa y roe es el apalancamiento
B26: aumento el margen, aumento la eficiencia, pese aque el apalancamiento a decrecido
B28: el apalancamiento crece
B30: ANALISIS DE RENTABILIDAD Y LIQUIDEZ CORRIENTE
B31: PRESENTACION DE 15 MIN
B32: DEBE ESTAR SUSTENTADA EN NUMEROS

Sheet TEORIA
B2: DETALLE | C2: A | D2: B | E2: UNIDAD | G2: DETALLE | H2: A | I2: B
B3: precio de venta | C3: 10 | D3: 10 | E3: Bs/unidad | G3: ingreso bruto | H3: =C3*C6 -> 150000 | I3: =D3*D6 -> 216921.31
B4: costo variable unitario | C4: 5 | D4: 5 | E4: bs/unidad | G4: menos decuento | H4: =C6 -> 15000 | I4: =D7*D6 -> 43384.262
B5: costos fijo | C5: 50000 | D5: 50000 | E5: bs/mes | G5: ingreso neto | H5: =H3-H4 -> 135000 | I5: =I3-I4 -> 173537.05
B6: volumen d venta | C6: 15000 | D6: 21692.131 | E6: unidades/mes | G6: costo de venta | H6: =C4*C6 -> 75000 | I6: =D4*D6 -> 108460.66
B7: descuento | C7: 1 | D7: 2 | E7: bs/unidad | G7: utilidad bruta | H7: =H5-H6 -> 60000 | I7: =I5-I6 -> 65076.394
G8: gastos operativos | H8: =C5 -> 50000 | I8: =D5 -> 50000
G9: resultado operativo | H9: =H7-H8 -> 10000 | I9: =I7-I8 -> 15076.394
G11: MB | H11: =H7/H3 -> 0.4 | I11: =I7/I3 -> 0.3
G12: MO | H12: =H9/H3 -> 0.066666667 | I12: =I9/I3 -> 0.069501671
B14: LAS PERDIDAS DE MARGEN DEBEN SER COMPENSADAS CON VOLUMEN
B15: DE VENTAS | G15: el volumen no afecta al margen, sino al operativo
B17: SI EL MARGEN BRUTO CAE, POR AHÍ ES ESTRATEGICO, DEBERIA SUBIR EL OPERATIVO | G17: si sube el precio, aumenta el bruto
B18: PERO SI CAEN AMBOS ESTA MUY MAL | G18: margen oper es lo que nos queda despues costo de venta y gastos operativos
G19: una mejora en el operativo si aumenta el precio
B20: MARGEN BRUTO es negativo si el costo esta encima del precio de venta
B21: el negocio genera margen bruto, tiene que ser positivo siempre | G21: bruto, cambios en el precio, costos y polita de descuento
B22: pero puede ser negativo cuando el sector que analisis es tomador de precio | G22: ir a notas y sacar el bruto y el descuento para el analisis
B23: osea que el precio no lo define la empresa sino el mercado internacional | G23: si aumentamos descuento matamos el margen bruto
G24: las perdidas de margen (descuento) debe ser recopensada con volumen de ventas
B25: LAS EMPRESAS MANEJAN PORTAFOLIOS DE PRODUCTOS | G25: si el area comercial me dice propongo un descuento
B26: COSTO ESTA ENCIMA DEL PRECIO, ESTRATEGIA DE PLATOS | G26: cuales son las ventas de equilibrio, cato es lo minimo que deberia vender el area comercial para que no afecte mi margen operativo, mi rentabilidad
B27: PRECIO BAJO PERO COMPRA VARIOS | G27: cuanto volumen de venta de mercado deberia de ver para que no muera el margen operativo
B29: PUEDE SER NEGATIVO A NIVEL DE PRODUCTO POR ESTRATEGIA DE LA EMPRESA (MARGEN BRUTO)
B32: LIQUIDEZ CORREINTE:
B33: capacidad de una empresa para pagar sus deudas de corto plazo (es decir aquellas que vencen en menos de un año)
B34: Mayor a 1: la empresa tiene más activos de corto plazo que deudas de corto plazo → buena señal.
B35: Igual a 1: la empresa justo alcanza a cubrir sus deudas con sus activos.
B36: Menor a 1: la empresa podría tener problemas para cumplir con sus obligaciones a corto plazo → señal de alerta.
B38: LIQUIDEZ ACIDA:
B39: mide la capacidad de una empresa para pagar sus deudas de corto plazo, pero demanera mas estricta que la liquidez corriente
B40: mas estricta porque excluye los inventarios de los activos corrientes, ya que estos pueden tardas mas en convertierse en efectivo
B41: Mayor a 1: la empresa puede cubrir sus deudas a corto plazo sin vender inventarios → buena salud financiera.
B42: Menor a 1: podría tener dificultades para pagar sus deudas si no puede vender rápidamente sus inventarios
B44: LIQUIDEZ INMEDIATA:
... B52: ROA
B53: DETALLE | C53: 1 | D53: 2 | E53: 3
B54: RN | C54: 10 | D54: 15 | E54: 20
B55: AT | C55: 100 | D55: 200 | E55: 300
B57: ROA | C57: =C54/C55 -> 0.1 | D57: =D54/D55 -> 0.075 | E57: =E54/E55 -> 0.066666667
...
